<?xml version="1.0"?>
<robot name="spacelab_robot" xmlns:xacro="http://www.ros.org/wiki/xacro">

  <!-- Include the macro for simple shape inertia calculation -->
  <xacro:include filename="inertial_macros.xacro"/>

  <!-- Add some parameters that will be post processed by xacro and replaced in the file -->
  <xacro:property name="PKG_Name" value="isaacsim_rviz_training" />

  <!-- Add some parameters that will be post processed by xacro and replaced in the file -->
  <xacro:property name="EE_mass" value="1.0" /> <!-- mass of the end effector -->
  <xacro:property name="EE_x_position" value="0.0" /> <!-- x position of the end effector -->
  <xacro:property name="EE_y_position" value="0.0845" /> <!-- y position of the end effector -->
  <xacro:property name="EE_z_position" value="0.0" /> <!-- z position of the end effector -->
  <xacro:property name="EEfinger_x_size" value="0.01" /> <!-- x size of the end effector fingers -->
  <xacro:property name="EEfinger_y_size" value="0.035" /> <!-- y size of the end effector fingers -->
  <xacro:property name="EEfinger_z_size" value="0.02" /> <!-- z size of the end effector fingers -->
  

  <!-- Definition of the end effector joint that is fixed -->
  <joint name="joint_7_EE" type="fixed" >
    <parent link="link_7" />
    <child link="link_EE" />
    <!-- Use the EE position parameter -->
    <origin xyz="${EE_x_position} ${EE_y_position} ${EE_z_position}" rpy="0 0 3.141592" />
  </joint>

  <!-- Definition of the end effector link that is fixed --> 
  <link name="link_EE" >
    <visual>
      <geometry>
        <mesh filename="package://${PKG_Name}/description/meshes/END_EFFECTOR.dae"/>
      </geometry>
    </visual>
    <collision>
      <geometry>
        <mesh filename="package://${PKG_Name}/description/meshes/END_EFFECTOR.dae"/>
      </geometry>
    </collision>
    <!-- <inertial>
      <origin xyz="0 0 0"/>
      <mass value="${EE_mass}"/>
      <inertia ixx="0.003" ixy="0" ixz="0"
          iyy="0.003" iyz="0"
          izz="0.009"/>
    </inertial> -->
  </link>

  <!-- Define the end effector gripper left finger -->
  <link name="link_Lgripper">
    <xacro:inertial_box mass="0.1" x="${EEfinger_x_size}" y="${EEfinger_y_size}" z="${EEfinger_z_size}">
        <origin xyz="0 0 0" rpy="0 0 0"/>
    </xacro:inertial_box>
    <!-- <inertial>
      <mass value="0.1"/>
      <origin xyz="0.0 0.0 0.0"/>
      <inertia ixx="0.001" ixy="0.0" ixz="0.0" iyy="0.001" iyz="0.0" izz="0.001"/>
    </inertial> -->
    <collision>
      <origin rpy="0 0 0" xyz="0.025 -0.238 0.0" />
      <geometry>
        <box size="${EEfinger_x_size} ${EEfinger_y_size} ${EEfinger_z_size}"/>
      </geometry>
    </collision>            
    <visual>
      <origin rpy="0 0 0" xyz="0.025 -0.238 0.0" />
      <geometry>
        <box size="${EEfinger_x_size} ${EEfinger_y_size} ${EEfinger_z_size}"/>
      </geometry>
      <material name="grey">
        <color rgba="0.2 0.2 0.2 1"/>
      </material>
    </visual>
  </link>        

  <!-- Define the prismatic joint between the end effector and the left finger -->
  <joint name="joint_EE_Lgripper" type="prismatic">
    <parent link="link_EE" />
    <child link="link_Lgripper" />
    <origin rpy="0 0 0" xyz="0 0 0" />
    <axis xyz="1 0 0" />
    <limit effort="500" lower="-0.02" upper="0.0" velocity="0.05"/>
    <dynamics damping="60.0" friction="4.0" />
  </joint>     

  <!-- Define the end effector gripper right finger -->
  <link name="link_Rgripper">
    <xacro:inertial_box mass="0.1" x="${EEfinger_x_size}" y="${EEfinger_y_size}" z="${EEfinger_z_size}">
        <origin xyz="0 0 0" rpy="0 0 0"/>
    </xacro:inertial_box>
    <!-- No inertia for links that are fixed otherwise error -->
    <!-- <inertial>
      <mass value="0.1"/>
      <origin xyz="0.0 0.0 0.0"/>
      <inertia ixx="0.001" ixy="0.0" ixz="0.0" iyy="0.001" iyz="0.0" izz="0.001"/>
    </inertial> -->
    <collision>
      <origin rpy="0 0 0" xyz="-0.025 -0.238 0.0" />
      <geometry>
        <box size="${EEfinger_x_size} ${EEfinger_y_size} ${EEfinger_z_size}"/>
      </geometry>
    </collision>            
    <visual>
      <origin rpy="0 0 0" xyz="-0.025 -0.238 0.0" />
      <geometry>
        <box size="${EEfinger_x_size} ${EEfinger_y_size} ${EEfinger_z_size}"/>
      </geometry>
      <material name="grey">
        <color rgba="0.2 0.2 0.2 1"/>
      </material>
    </visual>               
  </link>        

  <!-- Define the prismatic joint between the end effector and the right finger -->
  <joint name="joint_EE_Rgripper" type="prismatic">
    <parent link="link_EE" />
    <child link="link_Rgripper" />
    <origin rpy="0 0 0" xyz="0 0 0" />
    <axis xyz="1 0 0" />
    <limit effort="500" lower="0.0" upper="0.02" velocity="0.05"/>
    <dynamics damping="60.0" friction="4.0" />
  </joint>

</robot>
