<?xml version="1.0"?>
<robot name="spacelab_robot" xmlns:xacro="http://www.ros.org/wiki/xacro">

  <!-- Add some parameters that will be post processed by xacro and replaced in the file -->
  <xacro:property name="PKG_Name" value="isaacsim_rviz_training" />

  <!-- Material definition. These materials will be used for vizualisation in RVIZ -->
  <material name="black">
    <color rgba="0.0 0.0 0.0 1.0"/>
  </material>

  <material name="blue">
    <color rgba="0.0 0.0 0.8 1.0"/>
  </material>

  <material name="green">
    <color rgba="0.0 0.8 0.0 1.0"/>
  </material>

  <material name="grey">
    <color rgba="0.2 0.2 0.2 1.0"/>
  </material>

  <material name="orange">
    <color rgba="${255/255} ${108/255} ${10/255} 1.0"/>
  </material>

  <material name="brown">
    <color rgba="${222/255} ${207/255} ${195/255} 1.0"/>
  </material>

  <material name="red">
    <color rgba="0.8 0.0 0.0 1.0"/>
  </material>

  <material name="white">
    <color rgba="1.0 1.0 1.0 1.0"/>
  </material>

  <!-- Used for fixing robot to the world -->
  <link name="world"/>

  <!-- This first joint is fixed and link the world and the link_1 -->
  <joint name="joint_world_1" type="fixed">
    <parent link="world"/>
    <child link="link_1"/>
    <origin rpy="0.0 0.0 0.0" xyz="0.0 0.0 0.5"/>
  </joint>

  <!-- Definition of the baselink corresponding to the robot base --> 
  <link name="link_1">
    <visual>
      <geometry>
        <!-- it possible to define the absolute path of the model 
        <mesh filename="file:///home/spacefactory/ros2_ws_training/src/${PKG_Name}/description/meshes/Base.dae"/> -->
        <!-- but it's prefered to define the path relatively to the package -->
        <mesh filename="package://${PKG_Name}/description/meshes/Base.dae"/>
      </geometry>
      <material name="LightGrey">
        <color rgba="0.7 0.7 0.7 1.0"/>
      </material>
    </visual>
    <collision>
      <geometry>
        <mesh filename="package://${PKG_Name}/description/meshes/Base.dae"/>
      </geometry>
    </collision>
    <inertial>
      <mass value="4.0"/>
      <origin rpy="0.0 0.0 0.0" xyz="0.0 0.0 0.0"/>
      <inertia ixx="0.0061063308908" ixy="0.0" ixz="0.0" iyy="0.0061063308908" iyz="0.0" izz="0.01125"/>
    </inertial>
  </link>
  
  <!-- Definition of the 1st joint --> 
  <joint name="joint_1_2" type="revolute">
    <parent link="link_1"/>
    <child link="link_2"/>
    <origin rpy="0.0 0.0 0.0" xyz="0.0 0.0 0.1273"/>
    <axis xyz="0 0 1"/>
    <limit effort="330.0" lower="-3.14159265" upper="3.14159265" velocity="2.16"/>
    <dynamics damping="10.0" friction="10.0"/>
  </joint>

  <!-- Definition of the 1st movable part of the robot --> 
  <link name="link_2">
    <visual>
      <geometry>
        <mesh filename="package://${PKG_Name}/description/meshes/Shoulder.dae"/>
      </geometry>
      <material name="LightGrey">
        <color rgba="0.7 0.7 0.7 1.0"/>
      </material>
    </visual>
    <collision>
      <geometry>
        <mesh filename="package://${PKG_Name}/description/meshes/Shoulder.dae"/>
      </geometry>
    </collision>
    <inertial>
      <mass value="7.778"/>
      <origin rpy="0 0 0" xyz="0.0 0.0 0.0"/>
      <inertia ixx="0.0314743125769" ixy="0.0" ixz="0.0" iyy="0.0314743125769" iyz="0.0" izz="0.021875625"/>
    </inertial>
  </link>
  
  <!-- Definition of the 2nd joint -->
  <joint name="joint_2_3" type="revolute">
    <parent link="link_2"/>
    <child link="link_3"/>
    <origin rpy="0.0 1.570796325 0.0" xyz="0.0 0.220941 0.0"/>
    <axis xyz="0 1 0"/>
    <limit effort="330.0" lower="-3.14159265" upper="3.14159265" velocity="2.16"/>
    <dynamics damping="10.0" friction="10.0"/>
  </joint>

  <!-- Definition of the 2nd movable part of the robot --> 
  <link name="link_3">
    <visual>
      <geometry>
        <mesh filename="package://${PKG_Name}/description/meshes/UpperArm.dae"/>
      </geometry>
      <material name="LightGrey">
        <color rgba="0.7 0.7 0.7 1.0"/>
      </material>
    </visual>
    <collision>
      <geometry>
        <mesh filename="package://${PKG_Name}/description/meshes/UpperArm.dae"/>
      </geometry>
    </collision>
    <inertial>
      <mass value="12.93"/>
      <origin rpy="0 0 0" xyz="0.0 0.0 0.306"/>
      <inertia ixx="0.421753803798" ixy="0.0" ixz="0.0" iyy="0.421753803798" iyz="0.0" izz="0.036365625"/>
    </inertial>
  </link>
  
  <!-- Definition of the 3rd joint -->
  <joint name="joint_3_4" type="revolute">
    <parent link="link_3"/>
    <child link="link_4"/>
    <origin rpy="0.0 0.0 0.0" xyz="0.0 -0.1719 0.612"/>
    <axis xyz="0 1 0"/>
    <limit effort="150.0" lower="-3.14159265" upper="3.14159265" velocity="3.15"/>
    <dynamics damping="10.0" friction="10.0"/>
  </joint>

  <!-- Definition of the 3rd movable part of the robot --> 
  <link name="link_4">
    <visual>
      <geometry>
        <mesh filename="package://${PKG_Name}/description/meshes/Forearm.dae"/>
      </geometry>
      <material name="LightGrey">
        <color rgba="0.7 0.7 0.7 1.0"/>
      </material>
    </visual>
    <collision>
      <geometry>
        <mesh filename="package://${PKG_Name}/description/meshes/Forearm.dae"/>
      </geometry>
    </collision>
    <inertial>
      <mass value="3.87"/>
      <origin rpy="0 0 0" xyz="0.0 0.0 0.28615"/>
      <inertia ixx="0.111069694097" ixy="0.0" ixz="0.0" iyy="0.111069694097" iyz="0.0" izz="0.010884375"/>
    </inertial>
  </link>

  <!-- Definition of the 4th joint -->
  <joint name="joint_4_5" type="revolute">
    <parent link="link_4"/>
    <child link="link_5"/>
    <origin rpy="0.0 1.570796325 0.0" xyz="0.0 0.0 0.5723"/>
    <axis xyz="0 1 0"/>
    <limit effort="54.0" lower="-3.14159265" upper="3.14159265" velocity="3.2"/>
    <dynamics damping="10.0" friction="10.0"/>
  </joint>

  <!-- Definition of the 4th movable part of the robot --> 
  <link name="link_5">
    <visual>
      <geometry>
        <mesh filename="package://${PKG_Name}/description/meshes/Wrist1.dae"/>
      </geometry>
      <material name="LightGrey">
        <color rgba="0.7 0.7 0.7 1.0"/>
      </material>
    </visual>
    <collision>
      <geometry>
        <mesh filename="package://${PKG_Name}/description/meshes/Wrist1.dae"/>
      </geometry>
    </collision>
    <inertial>
      <mass value="1.96"/>
      <origin rpy="0 0 0" xyz="0.0 0.0 0.0"/>
      <inertia ixx="0.0051082479567" ixy="0.0" ixz="0.0" iyy="0.0051082479567" iyz="0.0" izz="0.0055125"/>
    </inertial>
  </link>

  <!-- Definition of the 5th joint -->
  <joint name="joint_5_6" type="revolute">
    <parent link="link_5"/>
    <child link="link_6"/>
    <origin rpy="0.0 0.0 0.0" xyz="0.0 0.1149 0.0"/>
    <axis xyz="0 0 1"/>
    <limit effort="54.0" lower="-3.14159265" upper="3.14159265" velocity="3.2"/>
    <dynamics damping="10.0" friction="10.0"/>
  </joint>

  <!-- Definition of the 5th movable part of the robot --> 
  <link name="link_6">
    <visual>
      <geometry>
        <mesh filename="package://${PKG_Name}/description/meshes/Wrist2.dae"/>
      </geometry>
      <material name="LightGrey">
        <color rgba="0.7 0.7 0.7 1.0"/>
      </material>
    </visual>
    <collision>
      <geometry>
        <mesh filename="package://${PKG_Name}/description/meshes/Wrist2.dae"/>
      </geometry>
    </collision>
    <inertial>
      <mass value="1.96"/>
      <origin rpy="0 0 0" xyz="0.0 0.0 0.0"/>
      <inertia ixx="0.0051082479567" ixy="0.0" ixz="0.0" iyy="0.0051082479567" iyz="0.0" izz="0.0055125"/>
    </inertial>
  </link>
  
  <!-- Definition of the 6th joint -->
  <joint name="joint_6_7" type="revolute">
    <parent link="link_6"/>
    <child link="link_7"/>
    <origin rpy="0.0 0.0 0.0" xyz="0.0 0.0 0.1157"/>
    <axis xyz="0 1 0"/>
    <limit effort="54.0" lower="-3.14159265" upper="3.14159265" velocity="3.2"/>
    <dynamics damping="10.0" friction="10.0"/>
  </joint>

  <!-- Definition of the 6th movable part of the robot --> 
  <link name="link_7">
    <visual>
      <geometry>
        <mesh filename="package://${PKG_Name}/description/meshes/Wrist3.dae"/>
      </geometry>
      <material name="LightGrey">
        <color rgba="0.7 0.7 0.7 1.0"/>
      </material>
    </visual>
    <collision>
      <geometry>
        <mesh filename="package://${PKG_Name}/description/meshes/Wrist3.dae"/>
      </geometry>
    </collision>
    <inertial>
      <mass value="0.202"/>
      <origin rpy="0 0 0" xyz="0.0 0.0 0.0"/>
      <inertia ixx="0.000526462289415" ixy="0.0" ixz="0.0" iyy="0.000526462289415" iyz="0.0" izz="0.000568125"/>
    </inertial>
  </link>
  
</robot>
